2018-12-28 11:50:27,595 ERROR: Exception on /explore [GET] [in /Users/peregrinedunn/.pyenv/versions/3.5.2/envs/hipflask/lib/python3.5/site-packages/flask/app.py:1761]
Traceback (most recent call last):
  File "/Users/peregrinedunn/.pyenv/versions/3.5.2/envs/hipflask/lib/python3.5/site-packages/flask/app.py", line 2292, in wsgi_app
    response = self.full_dispatch_request()
  File "/Users/peregrinedunn/.pyenv/versions/3.5.2/envs/hipflask/lib/python3.5/site-packages/flask/app.py", line 1815, in full_dispatch_request
    rv = self.handle_user_exception(e)
  File "/Users/peregrinedunn/.pyenv/versions/3.5.2/envs/hipflask/lib/python3.5/site-packages/flask/app.py", line 1718, in handle_user_exception
    reraise(exc_type, exc_value, tb)
  File "/Users/peregrinedunn/.pyenv/versions/3.5.2/envs/hipflask/lib/python3.5/site-packages/flask/_compat.py", line 35, in reraise
    raise value
  File "/Users/peregrinedunn/.pyenv/versions/3.5.2/envs/hipflask/lib/python3.5/site-packages/flask/app.py", line 1811, in full_dispatch_request
    rv = self.preprocess_request()
  File "/Users/peregrinedunn/.pyenv/versions/3.5.2/envs/hipflask/lib/python3.5/site-packages/flask/app.py", line 2087, in preprocess_request
    rv = func()
  File "/Users/peregrinedunn/Documents/projects/perrydunn/flask-app/app/main/routes.py", line 16, in before_request
    g.search_form = SearchForm(request.form)
  File "/Users/peregrinedunn/.pyenv/versions/3.5.2/envs/hipflask/lib/python3.5/site-packages/wtforms/form.py", line 212, in __call__
    return type.__call__(cls, *args, **kwargs)
  File "/Users/peregrinedunn/Documents/projects/perrydunn/flask-app/app/main/forms.py", line 38, in __init__
    super(SearchForm, self).__init__(*args, **kwargs)
TypeError: __init__() got multiple values for argument 'formdata'
2018-12-28 11:50:28,821 ERROR: Exception on /index [GET] [in /Users/peregrinedunn/.pyenv/versions/3.5.2/envs/hipflask/lib/python3.5/site-packages/flask/app.py:1761]
Traceback (most recent call last):
  File "/Users/peregrinedunn/.pyenv/versions/3.5.2/envs/hipflask/lib/python3.5/site-packages/flask/app.py", line 2292, in wsgi_app
    response = self.full_dispatch_request()
  File "/Users/peregrinedunn/.pyenv/versions/3.5.2/envs/hipflask/lib/python3.5/site-packages/flask/app.py", line 1815, in full_dispatch_request
    rv = self.handle_user_exception(e)
  File "/Users/peregrinedunn/.pyenv/versions/3.5.2/envs/hipflask/lib/python3.5/site-packages/flask/app.py", line 1718, in handle_user_exception
    reraise(exc_type, exc_value, tb)
  File "/Users/peregrinedunn/.pyenv/versions/3.5.2/envs/hipflask/lib/python3.5/site-packages/flask/_compat.py", line 35, in reraise
    raise value
  File "/Users/peregrinedunn/.pyenv/versions/3.5.2/envs/hipflask/lib/python3.5/site-packages/flask/app.py", line 1811, in full_dispatch_request
    rv = self.preprocess_request()
  File "/Users/peregrinedunn/.pyenv/versions/3.5.2/envs/hipflask/lib/python3.5/site-packages/flask/app.py", line 2087, in preprocess_request
    rv = func()
  File "/Users/peregrinedunn/Documents/projects/perrydunn/flask-app/app/main/routes.py", line 16, in before_request
    g.search_form = SearchForm(request.form)
  File "/Users/peregrinedunn/.pyenv/versions/3.5.2/envs/hipflask/lib/python3.5/site-packages/wtforms/form.py", line 212, in __call__
    return type.__call__(cls, *args, **kwargs)
  File "/Users/peregrinedunn/Documents/projects/perrydunn/flask-app/app/main/forms.py", line 38, in __init__
    super(SearchForm, self).__init__(*args, **kwargs)
TypeError: __init__() got multiple values for argument 'formdata'
2018-12-28 11:51:47,970 INFO: Microblog startup [in /Users/peregrinedunn/Documents/projects/perrydunn/flask-app/app/__init__.py:75]
2018-12-28 11:52:47,450 INFO: Microblog startup [in /Users/peregrinedunn/Documents/projects/perrydunn/flask-app/app/__init__.py:75]
2018-12-28 11:52:54,422 ERROR: Exception on /search [GET] [in /Users/peregrinedunn/.pyenv/versions/3.5.2/envs/hipflask/lib/python3.5/site-packages/flask/app.py:1761]
Traceback (most recent call last):
  File "/Users/peregrinedunn/.pyenv/versions/3.5.2/envs/hipflask/lib/python3.5/site-packages/flask/app.py", line 2292, in wsgi_app
    response = self.full_dispatch_request()
  File "/Users/peregrinedunn/.pyenv/versions/3.5.2/envs/hipflask/lib/python3.5/site-packages/flask/app.py", line 1815, in full_dispatch_request
    rv = self.handle_user_exception(e)
  File "/Users/peregrinedunn/.pyenv/versions/3.5.2/envs/hipflask/lib/python3.5/site-packages/flask/app.py", line 1718, in handle_user_exception
    reraise(exc_type, exc_value, tb)
  File "/Users/peregrinedunn/.pyenv/versions/3.5.2/envs/hipflask/lib/python3.5/site-packages/flask/_compat.py", line 35, in reraise
    raise value
  File "/Users/peregrinedunn/.pyenv/versions/3.5.2/envs/hipflask/lib/python3.5/site-packages/flask/app.py", line 1813, in full_dispatch_request
    rv = self.dispatch_request()
  File "/Users/peregrinedunn/.pyenv/versions/3.5.2/envs/hipflask/lib/python3.5/site-packages/flask/app.py", line 1799, in dispatch_request
    return self.view_functions[rule.endpoint](**req.view_args)
  File "/Users/peregrinedunn/.pyenv/versions/3.5.2/envs/hipflask/lib/python3.5/site-packages/flask_login/utils.py", line 261, in decorated_view
    return func(*args, **kwargs)
  File "/Users/peregrinedunn/Documents/projects/perrydunn/flask-app/app/main/routes.py", line 123, in search
    if not g.search_form.validate():
  File "/Users/peregrinedunn/.pyenv/versions/3.5.2/envs/hipflask/lib/python3.5/site-packages/wtforms/form.py", line 310, in validate
    return super(Form, self).validate(extra)
  File "/Users/peregrinedunn/.pyenv/versions/3.5.2/envs/hipflask/lib/python3.5/site-packages/wtforms/form.py", line 152, in validate
    if not field.validate(self, extra):
  File "/Users/peregrinedunn/.pyenv/versions/3.5.2/envs/hipflask/lib/python3.5/site-packages/wtforms/fields/core.py", line 206, in validate
    stop_validation = self._run_validation_chain(form, chain)
  File "/Users/peregrinedunn/.pyenv/versions/3.5.2/envs/hipflask/lib/python3.5/site-packages/wtforms/fields/core.py", line 226, in _run_validation_chain
    validator(form, self)
TypeError: 'ValidationError' object is not callable
2018-12-28 11:52:59,360 ERROR: Exception on /search [GET] [in /Users/peregrinedunn/.pyenv/versions/3.5.2/envs/hipflask/lib/python3.5/site-packages/flask/app.py:1761]
Traceback (most recent call last):
  File "/Users/peregrinedunn/.pyenv/versions/3.5.2/envs/hipflask/lib/python3.5/site-packages/flask/app.py", line 2292, in wsgi_app
    response = self.full_dispatch_request()
  File "/Users/peregrinedunn/.pyenv/versions/3.5.2/envs/hipflask/lib/python3.5/site-packages/flask/app.py", line 1815, in full_dispatch_request
    rv = self.handle_user_exception(e)
  File "/Users/peregrinedunn/.pyenv/versions/3.5.2/envs/hipflask/lib/python3.5/site-packages/flask/app.py", line 1718, in handle_user_exception
    reraise(exc_type, exc_value, tb)
  File "/Users/peregrinedunn/.pyenv/versions/3.5.2/envs/hipflask/lib/python3.5/site-packages/flask/_compat.py", line 35, in reraise
    raise value
  File "/Users/peregrinedunn/.pyenv/versions/3.5.2/envs/hipflask/lib/python3.5/site-packages/flask/app.py", line 1813, in full_dispatch_request
    rv = self.dispatch_request()
  File "/Users/peregrinedunn/.pyenv/versions/3.5.2/envs/hipflask/lib/python3.5/site-packages/flask/app.py", line 1799, in dispatch_request
    return self.view_functions[rule.endpoint](**req.view_args)
  File "/Users/peregrinedunn/.pyenv/versions/3.5.2/envs/hipflask/lib/python3.5/site-packages/flask_login/utils.py", line 261, in decorated_view
    return func(*args, **kwargs)
  File "/Users/peregrinedunn/Documents/projects/perrydunn/flask-app/app/main/routes.py", line 123, in search
    if not g.search_form.validate():
  File "/Users/peregrinedunn/.pyenv/versions/3.5.2/envs/hipflask/lib/python3.5/site-packages/wtforms/form.py", line 310, in validate
    return super(Form, self).validate(extra)
  File "/Users/peregrinedunn/.pyenv/versions/3.5.2/envs/hipflask/lib/python3.5/site-packages/wtforms/form.py", line 152, in validate
    if not field.validate(self, extra):
  File "/Users/peregrinedunn/.pyenv/versions/3.5.2/envs/hipflask/lib/python3.5/site-packages/wtforms/fields/core.py", line 206, in validate
    stop_validation = self._run_validation_chain(form, chain)
  File "/Users/peregrinedunn/.pyenv/versions/3.5.2/envs/hipflask/lib/python3.5/site-packages/wtforms/fields/core.py", line 226, in _run_validation_chain
    validator(form, self)
TypeError: 'ValidationError' object is not callable
2018-12-28 11:54:46,819 INFO: Microblog startup [in /Users/peregrinedunn/Documents/projects/perrydunn/flask-app/app/__init__.py:75]
