2018-12-28 11:45:32,934 ERROR: Exception on /search [GET] [in /Users/peregrinedunn/.pyenv/versions/3.5.2/envs/hipflask/lib/python3.5/site-packages/flask/app.py:1761]
Traceback (most recent call last):
  File "/Users/peregrinedunn/.pyenv/versions/3.5.2/envs/hipflask/lib/python3.5/site-packages/flask/app.py", line 2292, in wsgi_app
    response = self.full_dispatch_request()
  File "/Users/peregrinedunn/.pyenv/versions/3.5.2/envs/hipflask/lib/python3.5/site-packages/flask/app.py", line 1815, in full_dispatch_request
    rv = self.handle_user_exception(e)
  File "/Users/peregrinedunn/.pyenv/versions/3.5.2/envs/hipflask/lib/python3.5/site-packages/flask/app.py", line 1718, in handle_user_exception
    reraise(exc_type, exc_value, tb)
  File "/Users/peregrinedunn/.pyenv/versions/3.5.2/envs/hipflask/lib/python3.5/site-packages/flask/_compat.py", line 35, in reraise
    raise value
  File "/Users/peregrinedunn/.pyenv/versions/3.5.2/envs/hipflask/lib/python3.5/site-packages/flask/app.py", line 1813, in full_dispatch_request
    rv = self.dispatch_request()
  File "/Users/peregrinedunn/.pyenv/versions/3.5.2/envs/hipflask/lib/python3.5/site-packages/flask/app.py", line 1799, in dispatch_request
    return self.view_functions[rule.endpoint](**req.view_args)
  File "/Users/peregrinedunn/.pyenv/versions/3.5.2/envs/hipflask/lib/python3.5/site-packages/flask_login/utils.py", line 261, in decorated_view
    return func(*args, **kwargs)
  File "/Users/peregrinedunn/Documents/projects/perrydunn/flask-app/app/main/routes.py", line 133, in search
    next_url=next_url, prev_url=prev_url)
  File "/Users/peregrinedunn/.pyenv/versions/3.5.2/envs/hipflask/lib/python3.5/site-packages/flask/templating.py", line 135, in render_template
    context, ctx.app)
  File "/Users/peregrinedunn/.pyenv/versions/3.5.2/envs/hipflask/lib/python3.5/site-packages/flask/templating.py", line 117, in _render
    rv = template.render(context)
  File "/Users/peregrinedunn/.pyenv/versions/3.5.2/envs/hipflask/lib/python3.5/site-packages/jinja2/environment.py", line 1008, in render
    return self.environment.handle_exception(exc_info, True)
  File "/Users/peregrinedunn/.pyenv/versions/3.5.2/envs/hipflask/lib/python3.5/site-packages/jinja2/environment.py", line 780, in handle_exception
    reraise(exc_type, exc_value, tb)
  File "/Users/peregrinedunn/.pyenv/versions/3.5.2/envs/hipflask/lib/python3.5/site-packages/jinja2/_compat.py", line 37, in reraise
    raise value.with_traceback(tb)
  File "/Users/peregrinedunn/Documents/projects/perrydunn/flask-app/app/main/templates/search.html", line 1, in top-level template code
    {% extends "base.html" %}
  File "/Users/peregrinedunn/Documents/projects/perrydunn/flask-app/app/main/templates/base.html", line 1, in top-level template code
    {% extends 'bootstrap/base.html' %}
  File "/Users/peregrinedunn/.pyenv/versions/3.5.2/envs/hipflask/lib/python3.5/site-packages/flask_bootstrap/templates/bootstrap/base.html", line 1, in top-level template code
    {% block doc -%}
  File "/Users/peregrinedunn/.pyenv/versions/3.5.2/envs/hipflask/lib/python3.5/site-packages/flask_bootstrap/templates/bootstrap/base.html", line 4, in block "doc"
    {%- block html %}
  File "/Users/peregrinedunn/.pyenv/versions/3.5.2/envs/hipflask/lib/python3.5/site-packages/flask_bootstrap/templates/bootstrap/base.html", line 20, in block "html"
    {% block body -%}
  File "/Users/peregrinedunn/.pyenv/versions/3.5.2/envs/hipflask/lib/python3.5/site-packages/flask_bootstrap/templates/bootstrap/base.html", line 23, in block "body"
    {% block content -%}
  File "/Users/peregrinedunn/Documents/projects/perrydunn/flask-app/app/main/templates/base.html", line 57, in block "content"
    {% block app_content %}{% endblock %}
  File "/Users/peregrinedunn/Documents/projects/perrydunn/flask-app/app/main/templates/search.html", line 13, in block "app_content"
    {{ _('Previous results') }}
jinja2.exceptions.UndefinedError: '_' is undefined
2018-12-28 11:46:09,635 INFO: Microblog startup [in /Users/peregrinedunn/Documents/projects/perrydunn/flask-app/app/__init__.py:75]
2018-12-28 11:50:16,675 INFO: Microblog startup [in /Users/peregrinedunn/Documents/projects/perrydunn/flask-app/app/__init__.py:75]
2018-12-28 11:50:23,270 ERROR: Exception on /index [GET] [in /Users/peregrinedunn/.pyenv/versions/3.5.2/envs/hipflask/lib/python3.5/site-packages/flask/app.py:1761]
Traceback (most recent call last):
  File "/Users/peregrinedunn/.pyenv/versions/3.5.2/envs/hipflask/lib/python3.5/site-packages/flask/app.py", line 2292, in wsgi_app
    response = self.full_dispatch_request()
  File "/Users/peregrinedunn/.pyenv/versions/3.5.2/envs/hipflask/lib/python3.5/site-packages/flask/app.py", line 1815, in full_dispatch_request
    rv = self.handle_user_exception(e)
  File "/Users/peregrinedunn/.pyenv/versions/3.5.2/envs/hipflask/lib/python3.5/site-packages/flask/app.py", line 1718, in handle_user_exception
    reraise(exc_type, exc_value, tb)
  File "/Users/peregrinedunn/.pyenv/versions/3.5.2/envs/hipflask/lib/python3.5/site-packages/flask/_compat.py", line 35, in reraise
    raise value
  File "/Users/peregrinedunn/.pyenv/versions/3.5.2/envs/hipflask/lib/python3.5/site-packages/flask/app.py", line 1811, in full_dispatch_request
    rv = self.preprocess_request()
  File "/Users/peregrinedunn/.pyenv/versions/3.5.2/envs/hipflask/lib/python3.5/site-packages/flask/app.py", line 2087, in preprocess_request
    rv = func()
  File "/Users/peregrinedunn/Documents/projects/perrydunn/flask-app/app/main/routes.py", line 16, in before_request
    g.search_form = SearchForm(request.form)
  File "/Users/peregrinedunn/.pyenv/versions/3.5.2/envs/hipflask/lib/python3.5/site-packages/wtforms/form.py", line 212, in __call__
    return type.__call__(cls, *args, **kwargs)
  File "/Users/peregrinedunn/Documents/projects/perrydunn/flask-app/app/main/forms.py", line 38, in __init__
    super(SearchForm, self).__init__(*args, **kwargs)
TypeError: __init__() got multiple values for argument 'formdata'
2018-12-28 11:50:25,348 ERROR: Exception on /index [GET] [in /Users/peregrinedunn/.pyenv/versions/3.5.2/envs/hipflask/lib/python3.5/site-packages/flask/app.py:1761]
Traceback (most recent call last):
  File "/Users/peregrinedunn/.pyenv/versions/3.5.2/envs/hipflask/lib/python3.5/site-packages/flask/app.py", line 2292, in wsgi_app
    response = self.full_dispatch_request()
  File "/Users/peregrinedunn/.pyenv/versions/3.5.2/envs/hipflask/lib/python3.5/site-packages/flask/app.py", line 1815, in full_dispatch_request
    rv = self.handle_user_exception(e)
  File "/Users/peregrinedunn/.pyenv/versions/3.5.2/envs/hipflask/lib/python3.5/site-packages/flask/app.py", line 1718, in handle_user_exception
    reraise(exc_type, exc_value, tb)
  File "/Users/peregrinedunn/.pyenv/versions/3.5.2/envs/hipflask/lib/python3.5/site-packages/flask/_compat.py", line 35, in reraise
    raise value
  File "/Users/peregrinedunn/.pyenv/versions/3.5.2/envs/hipflask/lib/python3.5/site-packages/flask/app.py", line 1811, in full_dispatch_request
    rv = self.preprocess_request()
  File "/Users/peregrinedunn/.pyenv/versions/3.5.2/envs/hipflask/lib/python3.5/site-packages/flask/app.py", line 2087, in preprocess_request
    rv = func()
  File "/Users/peregrinedunn/Documents/projects/perrydunn/flask-app/app/main/routes.py", line 16, in before_request
    g.search_form = SearchForm(request.form)
  File "/Users/peregrinedunn/.pyenv/versions/3.5.2/envs/hipflask/lib/python3.5/site-packages/wtforms/form.py", line 212, in __call__
    return type.__call__(cls, *args, **kwargs)
  File "/Users/peregrinedunn/Documents/projects/perrydunn/flask-app/app/main/forms.py", line 38, in __init__
    super(SearchForm, self).__init__(*args, **kwargs)
TypeError: __init__() got multiple values for argument 'formdata'
2018-12-28 11:50:26,188 ERROR: Exception on /index [GET] [in /Users/peregrinedunn/.pyenv/versions/3.5.2/envs/hipflask/lib/python3.5/site-packages/flask/app.py:1761]
Traceback (most recent call last):
  File "/Users/peregrinedunn/.pyenv/versions/3.5.2/envs/hipflask/lib/python3.5/site-packages/flask/app.py", line 2292, in wsgi_app
    response = self.full_dispatch_request()
  File "/Users/peregrinedunn/.pyenv/versions/3.5.2/envs/hipflask/lib/python3.5/site-packages/flask/app.py", line 1815, in full_dispatch_request
    rv = self.handle_user_exception(e)
  File "/Users/peregrinedunn/.pyenv/versions/3.5.2/envs/hipflask/lib/python3.5/site-packages/flask/app.py", line 1718, in handle_user_exception
    reraise(exc_type, exc_value, tb)
  File "/Users/peregrinedunn/.pyenv/versions/3.5.2/envs/hipflask/lib/python3.5/site-packages/flask/_compat.py", line 35, in reraise
    raise value
  File "/Users/peregrinedunn/.pyenv/versions/3.5.2/envs/hipflask/lib/python3.5/site-packages/flask/app.py", line 1811, in full_dispatch_request
    rv = self.preprocess_request()
  File "/Users/peregrinedunn/.pyenv/versions/3.5.2/envs/hipflask/lib/python3.5/site-packages/flask/app.py", line 2087, in preprocess_request
    rv = func()
  File "/Users/peregrinedunn/Documents/projects/perrydunn/flask-app/app/main/routes.py", line 16, in before_request
    g.search_form = SearchForm(request.form)
  File "/Users/peregrinedunn/.pyenv/versions/3.5.2/envs/hipflask/lib/python3.5/site-packages/wtforms/form.py", line 212, in __call__
    return type.__call__(cls, *args, **kwargs)
  File "/Users/peregrinedunn/Documents/projects/perrydunn/flask-app/app/main/forms.py", line 38, in __init__
    super(SearchForm, self).__init__(*args, **kwargs)
TypeError: __init__() got multiple values for argument 'formdata'
